Workbook
Name D: #REF!
Name HY: #REF!
Name JYJ: #REF!
Name MasterList: #REF!
Name MasterList: #REF!
Name MasterList: #REF!
Name MasterListPT: '[1]PostCode MasterList PT'!$A$3:$N$812
Name PostcodeDepot: #REF!
Name PostcodeDepot: #REF!
Name PostcodeDepot: #REF!
Name PostcodeDepotPT: #REF!
Name PostcodeDepotPT: #REF!
Name PostcodeDepotPT: #REF!
Name PostcodeDepotPT: #REF!
Name PostCodeMasterList: #REF!
Name PostCodeMasterList: #REF!
Name PostCodeMasterList: #REF!
Name PostcodeMasterList_v3: #REF!
Name PostcodeMasterList_v3: #REF!
Name PostcodeMasterList_v3: #REF!
Name Servicios: #REF!
Name Servicios: #REF!
Name Servicios: #REF!
Name Servicios: #REF!
Name SiriusAddressList: #REF!
Name SiriusAddressList: #REF!
Name SiriusAddressList: #REF!

Sheet Datos Cliente
C5: Nombre Cliente | D5: PLANTASUR 2026
C6: Fecha | D6: 46023
C7: Otros datos
C9: Fecha validez | D9: 46387

Sheet Tarifa Premium
Q4: ='Datos Cliente'!D5 -> PLANTASUR 2026
Q5: ='Datos Cliente'!D6 -> 46023
Q6: ='Datos Cliente'!D7 -> 0
D8: MQP | E8: QP | F8: EQP | G8: SEL | H8: HP | I8: ELP | J8: ELP | K8: ELP | L8: EP | M8: EP | N8: EP | O8: EP | P8: EP | Q8: FP | R8: FP | S8: FP | T8: FP | U8: FP
D9: Mini Quarter | E9: Quarter | F9: Super Euro Light | G9: Half | H9: Extra Light | K9: Euro Pallet | P9: Full
D10: 1 | E10: 1 | F10: 1 | G10: 1 | H10: 1 | I10: 2 | J10: 3 | K10: 1 | L10: 2 | M10: 3 | N10: 4 | O10: 5 | P10: 1 | Q10: 2 | R10: 3 | S10: 4 | T10: 5
D11: PREMIUM | E11: PREMIUM | F11: PREMIUM | G11: PREMIUM | H11: PREMIUM | I11: PREMIUM | J11: PREMIUM | K11: PREMIUM | L11: PREMIUM | M11: PREMIUM | N11: PREMIUM | O11: PREMIUM | P11: PREMIUM | Q11: PREMIUM | R11: PREMIUM | S11: PREMIUM | T11: PREMIUM
B12: 31 | C12: Zona 21 | D12: 37.07355 | E12: 39.39195 | F12: 44.86135 | G12: 46.18615 | H12: 47.663 | I12: 45.9242 | J12: 44.765 | K12: 49.6606 | L12: 47.87765 | M12: 46.7066 | N12: 46.12635 | O12: 45.525 | P12: 51.061 | Q12: 49.3222 | R12: 48.163 | S12: 47.57305 | T12: 47.01415 | U12: Zona 21
B13: 32 | C13: Zona 22 | D13: 38.70885 | E13: 42.33135 | F13: 48.69085 | G13: 51.15415 | H13: 51.62705 | I13: 49.8158 | J13: 48.6152 | K13: 53.754 | L13: 51.90775 | M13: 50.6734 | N13: 50.05095 | O13: 49.4496 | P13: 55.1596 | Q13: 53.338 | R13: 52.12705 | S13: 51.52675 | T13: 50.9161 | U13: Zona 22
B14: 33 | C14: Zona 23 | D14: 39.6921 | E14: 44.44275 | F14: 50.7505 | G14: 53.1931 | H14: 54.2456 | I14: 52.4447 | J14: 51.27515 | K14: 56.99285 | L14: 55.1888 | M14: 53.97555 | N14: 53.3531 | O14: 52.7623 | P14: 58.29565 | Q14: 56.51545 | R14: 55.3252 | S14: 54.7456 | T14: 54.13495 | U14: Zona 23
B15: 34 | C15: Zona 24 | D15: 41.3895 | E15: 46.32645 | F15: 52.5928 | G15: 55.2424 | H15: 57.5783 | I15: 55.72565 | J15: 54.494 | K15: 60.4638 | L15: 58.5859 | M15: 57.33045 | N15: 56.69745 | O15: 56.075 | P15: 61.77325 | Q15: 59.9206 | R15: 58.68895 | S15: 58.0783 | T15: 57.4573 | U15: Zona 24
B16: 35 | C16: Zona 25 | D16: 42.80745 | E16: 47.5995 | F16: 54.4144 | G16: 57.59185 | H16: 59.8553 | I16: 58.0544 | J16: 56.8538 | K16: 62.7426 | L16: 60.9069 | M16: 59.6831 | N16: 59.0712 | O16: 58.4593 | P16: 63.94675 | Q16: 62.1562 | R16: 60.9556 | S16: 60.3553 | T16: 59.755 | U16: Zona 25
B17: 1 | C17: Zona 1 | D17: 39.4816 | E17: 41.81035 | F17: 53.67715 | G17: 58.52735 | H17: 58.60695 | I17: 56.86815 | J17: 55.10865 | K17: 61.8961 | L17: 60.1237 | M17: 58.3302 | N17: 57.74995 | O17: 57.1486 | P17: 63.1952 | Q17: 61.4357 | R17: 59.6969 | S17: 59.10695 | T17: 58.52735 | U17: Zona 1
B18: 2 | C18: Zona 2 | D18: 40.65115 | E18: 42.9799 | F18: 54.8467 | G18: 59.6969 | H18: 59.7765 | I18: 58.02735 | J18: 56.2782 | K18: 65.462 | L18: 63.6896 | M18: 60.7145 | N18: 60.1237 | O18: 59.52235 | P18: 66.68315 | Q18: 64.934 | R18: 62.02565 | S18: 61.4357 | T18: 60.8561 | U18: Zona 2
B19: 3 | C19: Zona 3 | D19: 41.99665 | E19: 44.3254 | F19: 56.7097 | G19: 62.2016 | H19: 62.87115 | I19: 61.11165 | J19: 60.5424 | K19: 69.20725 | L19: 67.43485 | M19: 64.4492 | N19: 63.86895 | O19: 63.2676 | P19: 70.3574 | Q19: 68.60825 | R19: 65.6999 | S19: 65.10995 | T19: 64.53035 | U19: Zona 3
B20: 4 | C20: Zona 4 | D20: 45.4846 | E20: 47.8237 | F20: 59.74225 | G20: 64.53035 | H20: 68.10825 | I20: 66.36945 | J20: 65.7795 | K20: 76.3285 | L20: 74.5561 | M20: 70.9902 | N20: 70.38885 | O20: 69.79805 | P20: 77.354 | Q20: 75.5945 | R20: 72.10655 | S20: 71.52695 | T20: 70.937 | U20: Zona 4
B21: 5 | C21: Zona 5 | D21: 47.6167 | E21: 49.9972 | F21: 62.20555 | G21: 67.418 | H21: 71.66865 | I21: 69.8781 | J21: 69.28815 | K21: 81.3081 | L21: 79.48295 | M21: 74.65105 | N21: 74.0497 | O21: 73.4378 | P21: 82.8602 | Q21: 81.06965 | R21: 76.319 | S21: 75.7394 | T21: 75.1391 | U21: Zona 5
B22: 6 | C22: Zona 6 | D22: 48.80695 | E22: 52.9573 | F22: 66.34555 | G22: 73.3589 | H22: 77.5992 | I22: 75.819 | J22: 75.2394 | K22: 90.3811 | L22: 87.9546 | M22: 84.94785 | N22: 83.7346 | O22: 82.52135 | P22: 94.73165 | Q22: 92.3615 | R22: 89.3807 | S22: 88.19045 | T22: 87.0002 | U22: Zona 6
B23: 7 | C23: Zona 7 | D23: 49.57285 | E23: 53.6404 | F23: 70.2268 | G23: 82.0115 | H23: 87.91815 | I23: 86.169 | J23: 85.57905 | K23: 102.46085 | L23: 100.0871 | M23: 97.12255 | N23: 95.94095 | O23: 94.7488 | P23: 106.4789 | Q23: 104.15015 | R23: 101.23145 | S23: 100.07225 | T23: 98.9027 | U23: Zona 7
... B30: 14 | C30: Zona 14 | D30: 145.055 | E30: 194.735 | F30: 297.29 | G30: 275.52 | H30: 361.96 | I30: 361.96 | J30: 361.96 | K30: 368.66 | L30: 368.66 | M30: 368.66 | N30: 368.66 | O30: 368.66 | P30: 372.81 | Q30: 372.81 | R30: 372.81 | S30: 372.81 | T30: 372.81 | U30: Zona 14
C32: Zona 21: | D32: Jaén
C33: Zona 22: | D33: Córdoba
C34: Zona 23: | D34: Albacete, Almería, Ciudad Real, Sevilla, Málaga
C35: Zona 24: | D35: Badajoz, Cuenca, Huelva, Murcia
C36: Zona 25: | D36: Alicante, Cádiz
C37: Zona 1: | D37: Guadalajara, Madrid
C38: Zona 2: | D38: Soria, Toledo, Guadalajara: 19261, 1928-19287, 19300-19392, 19432-19445
D39: 19460-19463, 19492, 19495
C40: Zona 3: | D40: Ávila, Burgos, La Rioja, Segovia, Valladolid, Zaragoza
C41: Zona 4: | D41: Álava, Huesca, León excepto CP Zona 11, Navarra, Palencia, Salamanca, Teruel, Valencia, Zamora
C42: Zona 5: | D42: Castellón, Guipuzcoa , Lérida
D43: Asturias, Cantabria, Tarragona, Vizcaya
C44: Zona 6: | D44: Barcelona, Cáceres
D45: León: 24100-24114, 24139-24140, 24300-24319, 24360-24380, 24384-24390, 24394-24395
D46: 24398-24479, 24480-24488, 24490-24498, 24500-24569, 24700-24710, 24714-24718,
D47: 24720-24750, 24764-24767, 24793-24795
D48: Asturias: 33700-33720, 33724-33736, 33740-33747,33749-33750, 33757-33785,
D49: 33787-33819, 33827, 33830-33839, 33842-33860, 33866-33885, 33887-33891
C50: Zona 7: | D50: Coruña, Gerona, Lugo, Orense, Pontevedra, Lérida: 25530, 25537-25540, 25548-25551,
D51: 25598, 25599, 25720-25721, 25724, 25726, 25727
...

Sheet Tarifa Economy
Q4: ='Datos Cliente'!D5 -> PLANTASUR 2026
Q5: ='Datos Cliente'!D6 -> 46023
Q6: ='Datos Cliente'!D7 -> 0
D8: MQP | E8: QP | F8: EQP | G8: SEL | H8: HP | I8: ELP | J8: ELP | K8: ELP | L8: EP | M8: EP | N8: EP | O8: EP | P8: EP | Q8: FP | R8: FP | S8: FP | T8: FP | U8: FP
D9: Mini Quarter | E9: Quarter | F9: Super Euro Light | G9: Half | H9: Extra Light | K9: Euro Pallet | P9: Full
D10: 1 | E10: 1 | F10: 1 | G10: 1 | H10: 1 | I10: 2 | J10: 3 | K10: 1 | L10: 2 | M10: 3 | N10: 4 | O10: 5 | P10: 1 | Q10: 2 | R10: 3 | S10: 4 | T10: 5
D11: ECONOMY | E11: ECONOMY | F11: ECONOMY | G11: ECONOMY | H11: ECONOMY | I11: ECONOMY | J11: ECONOMY | K11: ECONOMY | L11: ECONOMY | M11: ECONOMY | N11: ECONOMY | O11: ECONOMY | P11: ECONOMY | Q11: ECONOMY | R11: ECONOMY | S11: ECONOMY | T11: ECONOMY
B12: 31 | C12: Zona 21 | D12: 35.1435 | E12: 36.2915 | F12: 42.2035 | G12: 44.16125 | H12: 44.39925 | I12: 43.25125 | J12: 42.1135 | K12: 45.7503 | L12: 43.98425 | M12: 42.8243 | N12: 42.2391 | O12: 41.64345 | P12: 47.2055 | Q12: 45.4835 | R12: 44.3355 | S12: 43.75125 | T12: 43.17725 | U12: Zona 21
B13: 32 | C13: Zona 22 | D13: 36.681 | E13: 37.87 | F13: 44.807 | G13: 48.34325 | H13: 48.74525 | I13: 46.931 | J13: 45.742 | K13: 49.7004 | L13: 47.7358 | M13: 46.5236 | N13: 45.9175 | O13: 45.30095 | P13: 51.039 | Q13: 49.24525 | R13: 48.046 | S13: 47.431 | T13: 46.8365 | U13: Zona 22
B14: 33 | C14: Zona 23 | D14: 37.6855 | E14: 38.854 | F14: 46.21125 | G14: 50.4035 | H14: 51.359 | I14: 49.60625 | J14: 48.4275 | K14: 52.8563 | L14: 51.0589 | M14: 49.85715 | N14: 49.2615 | O14: 48.6554 | P14: 54.2165 | Q14: 52.4535 | R14: 51.285 | S14: 50.6905 | T14: 50.10625 | U14: Zona 23
B15: 34 | C15: Zona 24 | D15: 39.29475 | E15: 40.52475 | F15: 48.48675 | G15: 53.55025 | H15: 54.56725 | I15: 52.74275 | J15: 51.523 | K15: 56.14805 | L15: 54.2775 | M15: 53.03395 | N15: 52.4174 | O15: 51.7904 | P15: 57.517 | Q15: 55.68225 | R15: 54.4625 | S15: 53.8475 | T15: 53.24275 | U15: Zona 24
B16: 35 | C16: Zona 25 | D16: 40.74 | E16: 41.929 | F16: 50.27025 | G16: 55.918 | H16: 56.894 | I16: 55.12075 | J16: 53.93175 | K16: 58.4993 | L16: 56.681 | M16: 55.47925 | N16: 54.87315 | O16: 54.26705 | P16: 59.772 | Q16: 57.9885 | R16: 56.7995 | S16: 56.205 | T16: 55.62075 | U16: Zona 25
B17: 1 | C17: Zona 1 | D17: 37.519 | E17: 41.82525 | F17: 50.206 | G17: 55.322 | H17: 55.396 | I17: 53.674 | J17: 52.51575 | K17: 56.84845 | L17: 55.0824 | M17: 52.73115 | N17: 52.14595 | O17: 51.5503 | P17: 58.20225 | Q17: 56.48025 | R17: 54.174 | S17: 53.58975 | T17: 53.01575 | U17: Zona 1
B18: 2 | C18: Zona 2 | D18: 38.667 | E18: 42.9835 | F18: 51.58975 | G18: 57.05425 | H18: 57.1385 | I18: 55.98025 | J18: 54.822 | K18: 60.38055 | L18: 58.60405 | M18: 55.0824 | N18: 55.0824 | O18: 53.90155 | P18: 61.66675 | Q18: 59.94475 | R18: 57.05425 | S18: 56.48025 | T18: 55.322 | U18: Zona 2
B19: 3 | C19: Zona 3 | D19: 39.897 | E19: 44.20325 | F19: 53.322 | G19: 59.422 | H19: 59.496 | I19: 58.348 | J19: 57.18975 | K19: 63.9649 | L19: 62.2093 | M19: 58.08155 | N19: 57.49635 | O19: 56.9007 | P19: 64.6085 | Q19: 63.4605 | R19: 59.422 | S19: 58.848 | T19: 58.274 | U19: Zona 3
B20: 4 | C20: Zona 4 | D20: 43.3615 | E20: 47.66775 | F20: 55.864 | G20: 60.58025 | H20: 62.3865 | I20: 61.80225 | J20: 61.2385 | K20: 68.67785 | L20: 66.9118 | M20: 62.78405 | N20: 62.2093 | O20: 61.02845 | P20: 69.80525 | Q20: 68.08325 | R20: 63.4605 | S20: 62.8865 | T20: 62.30225 | U20: Zona 4
B21: 5 | C21: Zona 5 | D21: 44.82725 | E21: 49.18475 | F21: 57.65775 | G21: 62.77375 | H21: 65.2155 | I21: 64.63125 | J21: 64.03675 | K21: 72.85785 | L21: 71.05 | M21: 66.2639 | N21: 65.66825 | O21: 65.06215 | P21: 73.94625 | Q21: 72.18325 | R21: 67.48875 | S21: 66.89425 | T21: 66.31 | U21: Zona 5
B22: 6 | C22: Zona 6 | D22: 45.42175 | E22: 50.94775 | F22: 61.071 | G22: 68.65725 | H22: 70.5045 | I22: 69.91 | J22: 69.336 | K22: 78.85615 | L22: 76.4631 | M22: 71.6561 | N22: 71.05 | O22: 69.8587 | P22: 83.35575 | Q22: 80.99825 | R22: 75.7195 | S22: 75.125 | T22: 73.94625 | U22: Zona 6
B23: 7 | C23: Zona 7 | D23: 46.2315 | E23: 51.696 | F23: 64.05375 | G23: 74.99175 | H23: 77.9665 | I23: 77.3925 | J23: 76.80825 | K23: 89.26435 | L23: 86.9131 | M23: 81.6045 | N23: 81.0402 | O23: 79.85935 | P23: 93.46225 | Q23: 91.156 | R23: 85.38525 | S23: 84.8215 | T23: 83.66325 | U23: Zona 7
... B28: 12 | C28: Zona 17 | D28: 27 | E28: 27 | F28: 27 | G28: 27 | H28: 27 | I28: 27 | J28: 27 | K28: 31 | L28: 31 | M28: 31 | N28: 31 | O28: 31 | P28: 37 | Q28: 37 | R28: 37 | S28: 37 | T28: 37 | U28: Zona 17
B29: 13
B30: 14
C32: Zona 21: | D32: Jaén
C33: Zona 22: | D33: Córdoba
C34: Zona 23: | D34: Albacete, Almería, Ciudad Real, Sevilla, Málaga
C35: Zona 24: | D35: Badajoz, Cuenca, Huelva, Murcia
C36: Zona 25: | D36: Alicante, Cádiz
C37: Zona 1: | D37: Guadalajara, Madrid
C38: Zona 2: | D38: Soria, Toledo, Guadalajara: 19261, 1928-19287, 19300-19392, 19432-19445
D39: 19460-19463, 19492, 19495
C40: Zona 3: | D40: Ávila, Burgos, La Rioja, Segovia, Valladolid, Zaragoza
C41: Zona 4: | D41: Álava, Huesca, León excepto CP Zona 11, Navarra, Palencia, Salamanca, Teruel, Valencia, Zamora
C42: Zona 5: | D42: Castellón, Guipuzcoa , Lérida
D43: Asturias, Cantabria, Tarragona, Vizcaya
C44: Zona 6: | D44: Barcelona, Cáceres,
D45: León: 24100-24114, 24139-24140, 24300-24319, 24360-24380, 24384-24390, 24394-24395
D46: 24398-24479, 24480-24488, 24490-24498, 24500-24569, 24700-24710, 24714-24718,
D47: 24720-24750, 24764-24767, 24793-24795
D48: Asturias: 33700-33720, 33724-33736, 33740-33747,33749-33750, 33757-33785,
D49: 33787-33819, 33827, 33830-33839, 33842-33860, 33866-33885, 33887-33891
...

Sheet Cálculos 
F1: 1 | G1: 2 | H1: 3 | I1: 4 | J1: 5 | K1: 6 | L1: 7 | M1: 8 | N1: 9 | O1: 10 | P1: 11 | Q1: 12 | R1: 13 | S1: 14 | T1: 15 | U1: 16 | V1: 17 | W1: 18 | X1: 19 | Y1: 20 | Z1: 21 | AA1: 22
G3: IMR | M3: Hub fees | O3: Costes recogida arrastre | U3: Margen | W3: Total | AG3: Pallets Grandes | AN3: Pequeños
B4: Zona | C4: Hub | D4: BU | E4: Servicio | F4: Vlookup | G4: 1 | H4: 2 | I4: 3 | J4: 4 | K4: 5 | M4: 1 | O4: 1 | P4: 2 | Q4: 3 | R4: 4 | S4: 5 | U4: 1 | W4: 1 | X4: 2 | Y4: 3 | Z4: 4 | AA4: 5 | AG4: Hub | AH4: Hub Fee | AI4: PcLevy | AJ4: Marketing | AK4: Seguro | AL4: Total | AN4: Hub | AO4: Hub Fee | AP4: PcLevy | AQ4: Marketing | AR4: Seguro | AS4: Total
B5: 1 | C5: Madrid | D5: FP | E5: PREMIUM | F5: =B5&D5&E5 -> 1FPPREMIUM | G5: 25.5852 | H5: 23.8257 | I5: 22.0869 | J5: 21.49695 | K5: 20.91735 | M5: =VLOOKUP(C5,$AG$5:$AL$9,6,FALSE) -> 11.61 | O5: =#REF! -> #REF! | P5: =#REF! -> #REF! | Q5: =#REF! -> #REF! | R5: =#REF! -> #REF! | S5: =#REF! -> #REF! | U5: =#REF! -> #REF! | W5: =G5+$M5+O5+$U5 -> #REF! | X5: =H5+$M5+P5+$U5 -> #REF! | Y5: =I5+$M5+Q5+$U5 -> #REF! | Z5: =J5+$M5+R5+$U5 -> #REF! | AA5: =K5+$M5+S5+$U5 -> #REF! | AG5: Madrid | AH5: 10.45 | AI5: 0.32 | AJ5: 0.34 | AK5: 0.5 | AL5: =SUM(AH5:AK5) -> 11.61 | AN5: Madrid | AO5: 9.15 | AP5: 0.32 | AQ5: 0.34 | AR5: 0.5 | AS5: =SUM(AO5:AR5) -> 10.31
B6: 2 | C6: Madrid | D6: FP | E6: PREMIUM | F6: =B6&D6&E6 -> 2FPPREMIUM | G6: 29.07315 | H6: 27.324 | I6: 24.41565 | J6: 23.8257 | K6: 23.2461 | M6: =VLOOKUP(C6,$AG$5:$AL$9,6,FALSE) -> 11.61 | O6: =#REF! -> #REF! | P6: =#REF! -> #REF! | Q6: =#REF! -> #REF! | R6: =#REF! -> #REF! | S6: =#REF! -> #REF! | U6: =#REF! -> #REF! | W6: =G6+$M6+O6+$U6 -> #REF! | X6: =H6+$M6+P6+$U6 -> #REF! | Y6: =I6+$M6+Q6+$U6 -> #REF! | Z6: =J6+$M6+R6+$U6 -> #REF! | AA6: =K6+$M6+S6+$U6 -> #REF! | AG6: Zaragoza | AH6: 10.35 | AI6: 0.32 | AJ6: 0.34 | AK6: 0.5 | AL6: =SUM(AH6:AK6) -> 11.51 | AN6: Zaragoza | AO6: 9.05 | AP6: 0.32 | AQ6: 0.34 | AR6: 0.5 | AS6: =SUM(AO6:AR6) -> 10.21
B7: 3 | C7: Madrid | D7: FP | E7: PREMIUM | F7: =B7&D7&E7 -> 3FPPREMIUM | G7: 32.7474 | H7: 30.99825 | I7: 28.0899 | J7: 27.49995 | K7: 26.92035 | M7: =VLOOKUP(C7,$AG$5:$AL$9,6,FALSE) -> 11.61 | O7: =#REF! -> #REF! | P7: =#REF! -> #REF! | Q7: =#REF! -> #REF! | R7: =#REF! -> #REF! | S7: =#REF! -> #REF! | U7: =#REF! -> #REF! | W7: =G7+$M7+O7+$U7 -> #REF! | X7: =H7+$M7+P7+$U7 -> #REF! | Y7: =I7+$M7+Q7+$U7 -> #REF! | Z7: =J7+$M7+R7+$U7 -> #REF! | AA7: =K7+$M7+S7+$U7 -> #REF! | AG7: Hub-Sur | AH7: 9.65 | AI7: 0.32 | AJ7: 0.34 | AK7: 0.5 | AL7: =SUM(AH7:AK7) -> 10.81 | AN7: Hub-Sur | AO7: 9.05 | AP7: 0.32 | AQ7: 0.34 | AR7: 0.5 | AS7: =SUM(AO7:AR7) -> 10.21
B8: 4 | C8: Madrid | D8: FP | E8: PREMIUM | F8: =B8&D8&E8 -> 4FPPREMIUM | G8: 39.744 | H8: 37.9845 | I8: 34.49655 | J8: 33.91695 | K8: 33.327 | M8: =VLOOKUP(C8,$AG$5:$AL$9,6,FALSE) -> 11.61 | O8: =#REF! -> #REF! | P8: =#REF! -> #REF! | Q8: =#REF! -> #REF! | R8: =#REF! -> #REF! | S8: =#REF! -> #REF! | U8: =#REF! -> #REF! | W8: =G8+$M8+O8+$U8 -> #REF! | X8: =H8+$M8+P8+$U8 -> #REF! | Y8: =I8+$M8+Q8+$U8 -> #REF! | Z8: =J8+$M8+R8+$U8 -> #REF! | AA8: =K8+$M8+S8+$U8 -> #REF! | AG8: Barcelona | AH8: 8.6 | AI8: 0.32 | AJ8: 0.34 | AK8: 0.5 | AL8: =SUM(AH8:AK8) -> 9.76 | AN8: Barcelona | AO8: 8.1 | AP8: 0.32 | AQ8: 0.34 | AR8: 0.5 | AS8: =SUM(AO8:AR8) -> 9.26
B9: 5 | C9: Madrid | D9: FP | E9: PREMIUM | F9: =B9&D9&E9 -> 5FPPREMIUM | G9: 45.2502 | H9: 43.45965 | I9: 38.709 | J9: 38.1294 | K9: 37.5291 | M9: =VLOOKUP(C9,$AG$5:$AL$9,6,FALSE) -> 11.61 | O9: =#REF! -> #REF! | P9: =#REF! -> #REF! | Q9: =#REF! -> #REF! | R9: =#REF! -> #REF! | S9: =#REF! -> #REF! | U9: =#REF! -> #REF! | W9: =G9+$M9+O9+$U9 -> #REF! | X9: =H9+$M9+P9+$U9 -> #REF! | Y9: =I9+$M9+Q9+$U9 -> #REF! | Z9: =J9+$M9+R9+$U9 -> #REF! | AA9: =K9+$M9+S9+$U9 -> #REF! | AG9: Levante | AH9: 8.6 | AI9: 0.32 | AJ9: 0.34 | AK9: 0.5 | AL9: =SUM(AH9:AK9) -> 9.76 | AN9: Levante | AO9: 8.1 | AP9: 0.32 | AQ9: 0.34 | AR9: 0.5 | AS9: =SUM(AO9:AR9) -> 9.26
B10: 6 | C10: Madrid | D10: FP | E10: PREMIUM | F10: =B10&D10&E10 -> 6FPPREMIUM | G10: 57.12165 | H10: 54.7515 | I10: 51.7707 | J10: 50.58045 | K10: 49.3902 | M10: =VLOOKUP(C10,$AG$5:$AL$9,6,FALSE) -> 11.61 | O10: =#REF! -> #REF! | P10: =#REF! -> #REF! | Q10: =#REF! -> #REF! | R10: =#REF! -> #REF! | S10: =#REF! -> #REF! | U10: =#REF! -> #REF! | W10: =G10+$M10+O10+$U10 -> #REF! | X10: =H10+$M10+P10+$U10 -> #REF! | Y10: =I10+$M10+Q10+$U10 -> #REF! | Z10: =J10+$M10+R10+$U10 -> #REF! | AA10: =K10+$M10+S10+$U10 -> #REF!
B11: 7 | C11: Madrid | D11: FP | E11: PREMIUM | F11: =B11&D11&E11 -> 7FPPREMIUM | G11: 68.8689 | H11: 66.54015 | I11: 63.62145 | J11: 62.46225 | K11: 61.2927 | M11: =VLOOKUP(C11,$AG$5:$AL$9,6,FALSE) -> 11.61 | O11: =#REF! -> #REF! | P11: =#REF! -> #REF! | Q11: =#REF! -> #REF! | R11: =#REF! -> #REF! | S11: =#REF! -> #REF! | U11: =#REF! -> #REF! | W11: =G11+$M11+O11+$U11 -> #REF! | X11: =H11+$M11+P11+$U11 -> #REF! | Y11: =I11+$M11+Q11+$U11 -> #REF! | Z11: =J11+$M11+R11+$U11 -> #REF! | AA11: =K11+$M11+S11+$U11 -> #REF!
B12: 8 | C12: Madrid | D12: FP | E12: PREMIUM | F12: =B12&D12&E12 -> 8FPPREMIUM | G12: 102.16485 | H12: 99.1737 | I12: 96.20325 | J12: 95.00265 | K12: 93.8124 | M12: =VLOOKUP(C12,$AG$5:$AL$9,6,FALSE) -> 11.61 | O12: =#REF! -> #REF! | P12: =#REF! -> #REF! | Q12: =#REF! -> #REF! | R12: =#REF! -> #REF! | S12: =#REF! -> #REF! | U12: =#REF! -> #REF! | W12: =G12+$M12+O12+$U12 -> #REF! | X12: =H12+$M12+P12+$U12 -> #REF! | Y12: =I12+$M12+Q12+$U12 -> #REF! | Z12: =J12+$M12+R12+$U12 -> #REF! | AA12: =K12+$M12+S12+$U12 -> #REF!
B13: 9 | C13: Madrid | D13: FP | E13: PREMIUM | F13: =B13&D13&E13 -> 9FPPREMIUM | G13: 172.0584 | H13: 168.75675 | I13: 166.014 | J13: 162.71235 | K13: 159.42105 | M13: =VLOOKUP(C13,$AG$5:$AL$9,6,FALSE) -> 11.61 | O13: =#REF! -> #REF! | P13: =#REF! -> #REF! | Q13: =#REF! -> #REF! | R13: =#REF! -> #REF! | S13: =#REF! -> #REF! | U13: =#REF! -> #REF! | W13: =G13+$M13+O13+$U13 -> #REF! | X13: =H13+$M13+P13+$U13 -> #REF! | Y13: =I13+$M13+Q13+$U13 -> #REF! | Z13: =J13+$M13+R13+$U13 -> #REF! | AA13: =K13+$M13+S13+$U13 -> #REF!
B14: 10 | C14: Madrid | D14: FP | E14: PREMIUM | F14: =B14&D14&E14 -> 10FPPREMIUM | G14: 183.5883 | H14: 180.297 | I14: 176.99535 | J14: 173.70405 | K14: 170.41275 | M14: =VLOOKUP(C14,$AG$5:$AL$9,6,FALSE) -> 11.61 | O14: =#REF! -> #REF! | P14: =#REF! -> #REF! | Q14: =#REF! -> #REF! | R14: =#REF! -> #REF! | S14: =#REF! -> #REF! | U14: =#REF! -> #REF! | W14: =G14+$M14+O14+$U14 -> #REF! | X14: =H14+$M14+P14+$U14 -> #REF! | Y14: =I14+$M14+Q14+$U14 -> #REF! | Z14: =J14+$M14+R14+$U14 -> #REF! | AA14: =K14+$M14+S14+$U14 -> #REF!
B15: 11 | C15: Madrid | D15: FP | E15: PREMIUM | F15: =B15&D15&E15 -> 11FPPREMIUM | G15: 185.23395 | H15: 181.94265 | I15: 178.641 | J15: 175.3497 | K15: 172.60695 | M15: =VLOOKUP(C15,$AG$5:$AL$9,6,FALSE) -> 11.61 | O15: =#REF! -> #REF! | P15: =#REF! -> #REF! | Q15: =#REF! -> #REF! | R15: =#REF! -> #REF! | S15: =#REF! -> #REF! | U15: =#REF! -> #REF! | W15: =G15+$M15+O15+$U15 -> #REF! | X15: =H15+$M15+P15+$U15 -> #REF! | Y15: =I15+$M15+Q15+$U15 -> #REF! | Z15: =J15+$M15+R15+$U15 -> #REF! | AA15: =K15+$M15+S15+$U15 -> #REF!
B16: 12 | C16: Madrid | D16: FP | E16: PREMIUM | F16: =B16&D16&E16 -> 12FPPREMIUM | G16: 238.5054 | H16: 237.4083 | I16: 235.76265 | J16: 235.76265 | K16: 233.5581 | M16: =VLOOKUP(C16,$AG$5:$AL$9,6,FALSE) -> 11.61 | O16: =#REF! -> #REF! | P16: =#REF! -> #REF! | Q16: =#REF! -> #REF! | R16: =#REF! -> #REF! | S16: =#REF! -> #REF! | U16: =#REF! -> #REF! | W16: =G16+$M16+O16+$U16 -> #REF! | X16: =H16+$M16+P16+$U16 -> #REF! | Y16: =I16+$M16+Q16+$U16 -> #REF! | Z16: =J16+$M16+R16+$U16 -> #REF! | AA16: =K16+$M16+S16+$U16 -> #REF!
B17: 13 | C17: Madrid | D17: FP | E17: PREMIUM | F17: =B17&D17&E17 -> 13FPPREMIUM | G17: 299.115 | H17: 299.115 | I17: 299.115 | J17: 299.115 | K17: 299.115 | M17: =VLOOKUP(C17,$AG$5:$AL$9,6,FALSE) -> 11.61 | O17: =#REF! -> #REF! | P17: =#REF! -> #REF! | Q17: =#REF! -> #REF! | R17: =#REF! -> #REF! | S17: =#REF! -> #REF! | U17: =#REF! -> #REF! | W17: =G17+$M17+O17+$U17 -> #REF! | X17: =H17+$M17+P17+$U17 -> #REF! | Y17: =I17+$M17+Q17+$U17 -> #REF! | Z17: =J17+$M17+R17+$U17 -> #REF! | AA17: =K17+$M17+S17+$U17 -> #REF!
B18: 14 | C18: Madrid | D18: FP | E18: PREMIUM | F18: =B18&D18&E18 -> 14FPPREMIUM | G18: 331.2 | H18: 331.2 | I18: 331.2 | J18: 331.2 | K18: 331.2 | M18: =VLOOKUP(C18,$AG$5:$AL$9,6,FALSE) -> 11.61 | O18: =#REF! -> #REF! | P18: =#REF! -> #REF! | Q18: =#REF! -> #REF! | R18: =#REF! -> #REF! | S18: =#REF! -> #REF! | U18: =#REF! -> #REF! | W18: =G18+$M18+O18+$U18 -> #REF! | X18: =H18+$M18+P18+$U18 -> #REF! | Y18: =I18+$M18+Q18+$U18 -> #REF! | Z18: =J18+$M18+R18+$U18 -> #REF! | AA18: =K18+$M18+S18+$U18 -> #REF!
B19: 21 | C19: Zaragoza | D19: FP | E19: PREMIUM | F19: =B19&D19&E19 -> 21FPPREMIUM | G19: 20.58615 | H19: 18.837 | I19: 17.68815 | J19: 17.10855 | K19: 16.52895 | M19: =VLOOKUP(C19,$AG$5:$AL$9,6,FALSE) -> 11.51 | O19: =#REF! -> #REF! | P19: =#REF! -> #REF! | Q19: =#REF! -> #REF! | R19: =#REF! -> #REF! | S19: =#REF! -> #REF! | U19: =#REF! -> #REF! | W19: =G19+$M19+O19+$U19 -> #REF! | X19: =H19+$M19+P19+$U19 -> #REF! | Y19: =I19+$M19+Q19+$U19 -> #REF! | Z19: =J19+$M19+R19+$U19 -> #REF! | AA19: =K19+$M19+S19+$U19 -> #REF!
B20: 22 | C20: Zaragoza | D20: FP | E20: PREMIUM | F20: =B20&D20&E20 -> 22FPPREMIUM | G20: 24.47775 | H20: 22.11795 | I20: 20.9277 | J20: 20.33775 | K20: 19.7478 | M20: =VLOOKUP(C20,$AG$5:$AL$9,6,FALSE) -> 11.51 | O20: =#REF! -> #REF! | P20: =#REF! -> #REF! | Q20: =#REF! -> #REF! | R20: =#REF! -> #REF! | S20: =#REF! -> #REF! | U20: =#REF! -> #REF! | W20: =G20+$M20+O20+$U20 -> #REF! | X20: =H20+$M20+P20+$U20 -> #REF! | Y20: =I20+$M20+Q20+$U20 -> #REF! | Z20: =J20+$M20+R20+$U20 -> #REF! | AA20: =K20+$M20+S20+$U20 -> #REF!
B21: 23 | C21: Zaragoza | D21: FP | E21: PREMIUM | F21: =B21&D21&E21 -> 23FPPREMIUM | G21: 28.90755 | H21: 27.1584 | I21: 25.98885 | J21: 25.3989 | K21: 24.8193 | M21: =VLOOKUP(C21,$AG$5:$AL$9,6,FALSE) -> 11.51 | O21: =#REF! -> #REF! | P21: =#REF! -> #REF! | Q21: =#REF! -> #REF! | R21: =#REF! -> #REF! | S21: =#REF! -> #REF! | U21: =#REF! -> #REF! | W21: =G21+$M21+O21+$U21 -> #REF! | X21: =H21+$M21+P21+$U21 -> #REF! | Y21: =I21+$M21+Q21+$U21 -> #REF! | Z21: =J21+$M21+R21+$U21 -> #REF! | AA21: =K21+$M21+S21+$U21 -> #REF!
... B148: 54 | C148: Levante | D148: EP | E148: ECONOMY | F148: =B148&D148&E148 -> 54EPECONOMY | G148: 23.613 | H148: 22.134 | I148: 21.063 | J148: 20.502 | K148: 20.094 | M148: =VLOOKUP(C148,$AG$5:$AL$9,6,FALSE) -> 9.76 | O148: =#REF! -> #REF! | P148: =#REF! -> #REF! | Q148: =#REF! -> #REF! | R148: =#REF! -> #REF! | S148: =#REF! -> #REF! | U148: =#REF! -> #REF! | W148: =G148+$M148+O148+$U148 -> #REF! | X148: =H148+$M148+P148+$U148 -> #REF! | Y148: =I148+$M148+Q148+$U148 -> #REF! | Z148: =J148+$M148+R148+$U148 -> #REF! | AA148: =K148+$M148+S148+$U148 -> #REF!
B149: 1 | C149: Madrid | D149: ELP | E149: PREMIUM | F149: =B149&D149&E149 -> 1ELPPREMIUM | G149: 21.49695 | H149: 19.75815 | I149: 17.99865 | J149: 17.99865 | K149: 17.99865 | M149: =VLOOKUP(C149,$AG$5:$AL$9,6,FALSE) -> 11.61 | O149: =#REF! -> #REF! | P149: =#REF! -> #REF! | Q149: =#REF! -> #REF! | R149: =Q149 -> #REF! | S149: =R149 -> #REF! | U149: =#REF! -> #REF! | W149: =G149+$M149+O149+$U149 -> #REF! | X149: =H149+$M149+P149+$U149 -> #REF! | Y149: =I149+$M149+Q149+$U149 -> #REF! | Z149: =J149+$M149+R149+$U149 -> #REF! | AA149: =K149+$M149+S149+$U149 -> #REF!
B150: 2 | C150: Madrid | D150: ELP | E150: PREMIUM | F150: =B150&D150&E150 -> 2ELPPREMIUM | G150: 22.6665 | H150: 20.91735 | I150: 19.1682 | J150: 19.1682 | K150: 19.1682 | M150: =VLOOKUP(C150,$AG$5:$AL$9,6,FALSE) -> 11.61 | O150: =#REF! -> #REF! | P150: =#REF! -> #REF! | Q150: =#REF! -> #REF! | R150: =Q150 -> #REF! | S150: =R150 -> #REF! | U150: =#REF! -> #REF! | W150: =G150+$M150+O150+$U150 -> #REF! | X150: =H150+$M150+P150+$U150 -> #REF! | Y150: =I150+$M150+Q150+$U150 -> #REF! | Z150: =J150+$M150+R150+$U150 -> #REF! | AA150: =K150+$M150+S150+$U150 -> #REF!
B151: 3 | C151: Madrid | D151: ELP | E151: PREMIUM | F151: =B151&D151&E151 -> 3ELPPREMIUM | G151: 25.76115 | H151: 24.00165 | I151: 23.4324 | J151: 23.4324 | K151: 23.4324 | M151: =VLOOKUP(C151,$AG$5:$AL$9,6,FALSE) -> 11.61 | O151: =#REF! -> #REF! | P151: =#REF! -> #REF! | Q151: =#REF! -> #REF! | R151: =Q151 -> #REF! | S151: =R151 -> #REF! | U151: =#REF! -> #REF! | W151: =G151+$M151+O151+$U151 -> #REF! | X151: =H151+$M151+P151+$U151 -> #REF! | Y151: =I151+$M151+Q151+$U151 -> #REF! | Z151: =J151+$M151+R151+$U151 -> #REF! | AA151: =K151+$M151+S151+$U151 -> #REF!
B152: 4 | C152: Madrid | D152: ELP | E152: PREMIUM | F152: =B152&D152&E152 -> 4ELPPREMIUM | G152: 30.99825 | H152: 29.25945 | I152: 28.6695 | J152: 28.6695 | K152: 28.6695 | M152: =VLOOKUP(C152,$AG$5:$AL$9,6,FALSE) -> 11.61 | O152: =#REF! -> #REF! | P152: =#REF! -> #REF! | Q152: =#REF! -> #REF! | R152: =Q152 -> #REF! | S152: =R152 -> #REF! | U152: =#REF! -> #REF! | W152: =G152+$M152+O152+$U152 -> #REF! | X152: =H152+$M152+P152+$U152 -> #REF! | Y152: =I152+$M152+Q152+$U152 -> #REF! | Z152: =J152+$M152+R152+$U152 -> #REF! | AA152: =K152+$M152+S152+$U152 -> #REF!
B153: 5 | C153: Madrid | D153: ELP | E153: PREMIUM | F153: =B153&D153&E153 -> 5ELPPREMIUM | G153: 34.55865 | H153: 32.7681 | I153: 32.17815 | J153: 32.17815 | K153: 32.17815 | M153: =VLOOKUP(C153,$AG$5:$AL$9,6,FALSE) -> 11.61 | O153: =#REF! -> #REF! | P153: =#REF! -> #REF! | Q153: =#REF! -> #REF! | R153: =Q153 -> #REF! | S153: =R153 -> #REF! | U153: =#REF! -> #REF! | W153: =G153+$M153+O153+$U153 -> #REF! | X153: =H153+$M153+P153+$U153 -> #REF! | Y153: =I153+$M153+Q153+$U153 -> #REF! | Z153: =J153+$M153+R153+$U153 -> #REF! | AA153: =K153+$M153+S153+$U153 -> #REF!
B154: 6 | C154: Madrid | D154: ELP | E154: PREMIUM | F154: =B154&D154&E154 -> 6ELPPREMIUM | G154: 40.4892 | H154: 38.709 | I154: 38.1294 | J154: 38.1294 | K154: 38.1294 | M154: =VLOOKUP(C154,$AG$5:$AL$9,6,FALSE) -> 11.61 | O154: =#REF! -> #REF! | P154: =#REF! -> #REF! | Q154: =#REF! -> #REF! | R154: =Q154 -> #REF! | S154: =R154 -> #REF! | U154: =#REF! -> #REF! | W154: =G154+$M154+O154+$U154 -> #REF! | X154: =H154+$M154+P154+$U154 -> #REF! | Y154: =I154+$M154+Q154+$U154 -> #REF! | Z154: =J154+$M154+R154+$U154 -> #REF! | AA154: =K154+$M154+S154+$U154 -> #REF!
B155: 7 | C155: Madrid | D155: ELP | E155: PREMIUM | F155: =B155&D155&E155 -> 7ELPPREMIUM | G155: 50.80815 | H155: 49.059 | I155: 48.46905 | J155: 48.46905 | K155: 48.46905 | M155: =VLOOKUP(C155,$AG$5:$AL$9,6,FALSE) -> 11.61 | O155: =#REF! -> #REF! | P155: =#REF! -> #REF! | Q155: =#REF! -> #REF! | R155: =Q155 -> #REF! | S155: =R155 -> #REF! | U155: =#REF! -> #REF! | W155: =G155+$M155+O155+$U155 -> #REF! | X155: =H155+$M155+P155+$U155 -> #REF! | Y155: =I155+$M155+Q155+$U155 -> #REF! | Z155: =J155+$M155+R155+$U155 -> #REF! | AA155: =K155+$M155+S155+$U155 -> #REF!
B156: 8 | C156: Madrid | D156: ELP | E156: PREMIUM | F156: =B156&D156&E156 -> 8ELPPREMIUM | G156: 77.1075 | H156: 75.31695 | I156: 74.71665 | J156: 74.71665 | K156: 74.71665 | M156: =VLOOKUP(C156,$AG$5:$AL$9,6,FALSE) -> 11.61 | O156: =#REF! -> #REF! | P156: =#REF! -> #REF! | Q156: =#REF! -> #REF! | R156: =Q156 -> #REF! | S156: =R156 -> #REF! | U156: =#REF! -> #REF! | W156: =G156+$M156+O156+$U156 -> #REF! | X156: =H156+$M156+P156+$U156 -> #REF! | Y156: =I156+$M156+Q156+$U156 -> #REF! | Z156: =J156+$M156+R156+$U156 -> #REF! | AA156: =K156+$M156+S156+$U156 -> #REF!
B157: 9 | C157: Madrid | D157: ELP | E157: PREMIUM | F157: =B157&D157&E157 -> 9ELPPREMIUM | G157: 115.49565 | H157: 113.83965 | I157: 113.2911 | J157: 113.2911 | K157: 113.2911 | M157: =VLOOKUP(C157,$AG$5:$AL$9,6,FALSE) -> 11.61 | O157: =#REF! -> #REF! | P157: =#REF! -> #REF! | Q157: =#REF! -> #REF! | R157: =Q157 -> #REF! | S157: =R157 -> #REF! | U157: =#REF! -> #REF! | W157: =G157+$M157+O157+$U157 -> #REF! | X157: =H157+$M157+P157+$U157 -> #REF! | Y157: =I157+$M157+Q157+$U157 -> #REF! | Z157: =J157+$M157+R157+$U157 -> #REF! | AA157: =K157+$M157+S157+$U157 -> #REF!
B158: 10 | C158: Madrid | D158: ELP | E158: PREMIUM | F158: =B158&D158&E158 -> 10ELPPREMIUM | G158: 122.07825 | H158: 119.88405 | I158: 119.3355 | J158: 119.3355 | K158: 119.3355 | M158: =VLOOKUP(C158,$AG$5:$AL$9,6,FALSE) -> 11.61 | O158: =#REF! -> #REF! | P158: =#REF! -> #REF! | Q158: =#REF! -> #REF! | R158: =Q158 -> #REF! | S158: =R158 -> #REF! | U158: =#REF! -> #REF! | W158: =G158+$M158+O158+$U158 -> #REF! | X158: =H158+$M158+P158+$U158 -> #REF! | Y158: =I158+$M158+Q158+$U158 -> #REF! | Z158: =J158+$M158+R158+$U158 -> #REF! | AA158: =K158+$M158+S158+$U158 -> #REF!
B159: 11 | C159: Madrid | D159: ELP | E159: PREMIUM | F159: =B159&D159&E159 -> 11ELPPREMIUM | G159: 123.17535 | H159: 120.98115 | I159: 120.4326 | J159: 120.4326 | K159: 120.4326 | M159: =VLOOKUP(C159,$AG$5:$AL$9,6,FALSE) -> 11.61 | O159: =#REF! -> #REF! | P159: =#REF! -> #REF! | Q159: =#REF! -> #REF! | R159: =Q159 -> #REF! | S159: =R159 -> #REF! | U159: =#REF! -> #REF! | W159: =G159+$M159+O159+$U159 -> #REF! | X159: =H159+$M159+P159+$U159 -> #REF! | Y159: =I159+$M159+Q159+$U159 -> #REF! | Z159: =J159+$M159+R159+$U159 -> #REF! | AA159: =K159+$M159+S159+$U159 -> #REF!
B160: 12 | C160: Madrid | D160: ELP | E160: PREMIUM | F160: =B160&D160&E160 -> 12ELPPREMIUM | G160: 169.3053 | H160: 167.65965 | I160: 166.56255 | J160: 166.56255 | K160: 166.56255 | M160: =VLOOKUP(C160,$AG$5:$AL$9,6,FALSE) -> 11.61 | O160: =#REF! -> #REF! | P160: =#REF! -> #REF! | Q160: =#REF! -> #REF! | R160: =Q160 -> #REF! | S160: =R160 -> #REF! | U160: =#REF! -> #REF! | W160: =G160+$M160+O160+$U160 -> #REF! | X160: =H160+$M160+P160+$U160 -> #REF! | Y160: =I160+$M160+Q160+$U160 -> #REF! | Z160: =J160+$M160+R160+$U160 -> #REF! | AA160: =K160+$M160+S160+$U160 -> #REF!
... B220: 54 | C220: Levante | D220: ELP | E220: ECONOMY | F220: =B220&D220&E220 -> 54ELPECONOMY | G220: 22.55 | H220: 20.8 | I220: 19.7 | J220: 19.7 | K220: 19.7 | M220: =VLOOKUP(C220,$AG$5:$AL$9,6,FALSE) -> 9.76 | O220: =#REF! -> #REF! | P220: =#REF! -> #REF! | Q220: =#REF! -> #REF! | R220: =Q220 -> #REF! | S220: =R220 -> #REF! | U220: =#REF! -> #REF! | W220: =G220+$M220+O220+$U220 -> #REF! | X220: =H220+$M220+P220+$U220 -> #REF! | Y220: =I220+$M220+Q220+$U220 -> #REF! | Z220: =J220+$M220+R220+$U220 -> #REF! | AA220: =K220+$M220+S220+$U220 -> #REF!
B221: 1 | C221: Madrid | D221: HP | E221: PREMIUM | F221: =B221&D221&E221 -> 1HPPREMIUM | G221: 20.91735 | H221: 20.91735 | I221: 20.91735 | J221: 20.91735 | K221: 20.91735 | M221: =VLOOKUP(C221,$AG$5:$AL$9,6,FALSE) -> 11.61 | O221: =#REF! -> #REF! | P221: =O221 -> #REF! | Q221: =P221 -> #REF! | R221: =Q221 -> #REF! | S221: =R221 -> #REF! | U221: =#REF! -> #REF! | W221: =G221+$M221+O221+$U221 -> #REF! | X221: =H221+$M221+P221+$U221 -> #REF! | Y221: =I221+$M221+Q221+$U221 -> #REF! | Z221: =J221+$M221+R221+$U221 -> #REF! | AA221: =K221+$M221+S221+$U221 -> #REF!
B222: 2 | C222: Madrid | D222: HP | E222: PREMIUM | F222: =B222&D222&E222 -> 2HPPREMIUM | G222: 22.0869 | H222: 22.0869 | I222: 22.0869 | J222: 22.0869 | K222: 22.0869 | M222: =VLOOKUP(C222,$AG$5:$AL$9,6,FALSE) -> 11.61 | O222: =#REF! -> #REF! | P222: =O222 -> #REF! | Q222: =P222 -> #REF! | R222: =Q222 -> #REF! | S222: =R222 -> #REF! | U222: =#REF! -> #REF! | W222: =G222+$M222+O222+$U222 -> #REF! | X222: =H222+$M222+P222+$U222 -> #REF! | Y222: =I222+$M222+Q222+$U222 -> #REF! | Z222: =J222+$M222+R222+$U222 -> #REF! | AA222: =K222+$M222+S222+$U222 -> #REF!
B223: 3 | C223: Madrid | D223: HP | E223: PREMIUM | F223: =B223&D223&E223 -> 3HPPREMIUM | G223: 24.5916 | H223: 24.5916 | I223: 24.5916 | J223: 24.5916 | K223: 24.5916 | M223: =VLOOKUP(C223,$AG$5:$AL$9,6,FALSE) -> 11.61 | O223: =#REF! -> #REF! | P223: =O223 -> #REF! | Q223: =P223 -> #REF! | R223: =Q223 -> #REF! | S223: =R223 -> #REF! | U223: =#REF! -> #REF! | W223: =G223+$M223+O223+$U223 -> #REF! | X223: =H223+$M223+P223+$U223 -> #REF! | Y223: =I223+$M223+Q223+$U223 -> #REF! | Z223: =J223+$M223+R223+$U223 -> #REF! | AA223: =K223+$M223+S223+$U223 -> #REF!
B224: 4 | C224: Madrid | D224: HP | E224: PREMIUM | F224: =B224&D224&E224 -> 4HPPREMIUM | G224: 26.92035 | H224: 26.92035 | I224: 26.92035 | J224: 26.92035 | K224: 26.92035 | M224: =VLOOKUP(C224,$AG$5:$AL$9,6,FALSE) -> 11.61 | O224: =#REF! -> #REF! | P224: =O224 -> #REF! | Q224: =P224 -> #REF! | R224: =Q224 -> #REF! | S224: =R224 -> #REF! | U224: =#REF! -> #REF! | W224: =G224+$M224+O224+$U224 -> #REF! | X224: =H224+$M224+P224+$U224 -> #REF! | Y224: =I224+$M224+Q224+$U224 -> #REF! | Z224: =J224+$M224+R224+$U224 -> #REF! | AA224: =K224+$M224+S224+$U224 -> #REF!
B225: 5 | C225: Madrid | D225: HP | E225: PREMIUM | F225: =B225&D225&E225 -> 5HPPREMIUM | G225: 29.808 | H225: 29.808 | I225: 29.808 | J225: 29.808 | K225: 29.808 | M225: =VLOOKUP(C225,$AG$5:$AL$9,6,FALSE) -> 11.61 | O225: =#REF! -> #REF! | P225: =O225 -> #REF! | Q225: =P225 -> #REF! | R225: =Q225 -> #REF! | S225: =R225 -> #REF! | U225: =#REF! -> #REF! | W225: =G225+$M225+O225+$U225 -> #REF! | X225: =H225+$M225+P225+$U225 -> #REF! | Y225: =I225+$M225+Q225+$U225 -> #REF! | Z225: =J225+$M225+R225+$U225 -> #REF! | AA225: =K225+$M225+S225+$U225 -> #REF!
B226: 6 | C226: Madrid | D226: HP | E226: PREMIUM | F226: =B226&D226&E226 -> 6HPPREMIUM | G226: 35.7489 | H226: 35.7489 | I226: 35.7489 | J226: 35.7489 | K226: 35.7489 | M226: =VLOOKUP(C226,$AG$5:$AL$9,6,FALSE) -> 11.61 | O226: =#REF! -> #REF! | P226: =O226 -> #REF! | Q226: =P226 -> #REF! | R226: =Q226 -> #REF! | S226: =R226 -> #REF! | U226: =#REF! -> #REF! | W226: =G226+$M226+O226+$U226 -> #REF! | X226: =H226+$M226+P226+$U226 -> #REF! | Y226: =I226+$M226+Q226+$U226 -> #REF! | Z226: =J226+$M226+R226+$U226 -> #REF! | AA226: =K226+$M226+S226+$U226 -> #REF!
...
